<?xml version="1.0" ?>
<robot xmlns:xacro="http://ros.org/wiki/xacro" name="kuka_kr6r700">
  <link name="base_link">
  <!-- 缺乏物理参数，需要机器关节的质量等信息 -->
    <inertial>
      <origin xyz="0.0 0.0 0.0" rpy="0.0 0.0 0.0"/>
      <mass value="1.0"/>
      <inertia ixx="0.0" ixy="0.0" ixz="0.0" iyy="0.0" iyz="0.0" izz="0.0"/>
    </inertial>
    <visual>
      <origin rpy="0 0 0" xyz="0 0 0"/>
      <geometry>
        <mesh filename="package://kuka_kr6_support/meshes/kr6_agilus/visual/base_link.dae"/>
      </geometry>
      <xacro:material_kuka_pedestal />
    </visual>
    <collision>
      <!-- <origin xyz="0.0 0.0 0.0" rpy="0.0 0.0 0.0"/> -->
      <geometry>
        <mesh filename="package://kuka_kr6_support/meshes/kr6_agilus/collision/base_link.stl"/>        
      </geometry>
    </collision>
  </link>
  <link name="link_1">
  <inertial>
      <origin xyz="0.0 0.0 0.0" rpy="0.0 0.0 0.0"/>
      <mass value="1.0"/>
      <inertia ixx="0.0" ixy="0.0" ixz="0.0" iyy="0.0" iyz="0.0" izz="0.0"/>
    </inertial>
    <visual>
      <origin rpy="0 0 0" xyz="0 0 0"/>
      <geometry>
        <mesh filename="package://kuka_kr6_support/meshes/kr6_agilus/visual/link_1.dae"/>
      </geometry>
      <xacro:material_kuka_orange />
    </visual>
    <collision>
      <!-- <origin xyz="0.0 0.0 0.0" rpy="0.0 0.0 0.0"/> -->
      <geometry>
        <mesh filename="package://kuka_kr6_support/meshes/kr6_agilus/collision/link_1.stl"/>        
      </geometry>
    </collision>
  </link>
  <link name="link_2">
  <inertial>
      <origin xyz="0.0 0.0 0.0" rpy="0.0 0.0 0.0"/>
      <mass value="1.0"/>
      <inertia ixx="0.0" ixy="0.0" ixz="0.0" iyy="0.0" iyz="0.0" izz="0.0"/>
    </inertial>
    <visual>
      <origin rpy="0 0 0" xyz="0 0 0"/>
      <geometry>
        <mesh filename="package://kuka_kr6_support/meshes/kr6r700sixx/visual/link_2.dae"/>
      </geometry>
      <xacro:material_kuka_orange />
    </visual>
    <collision>
      <!-- <origin xyz="0.0 0.0 0.0" rpy="0.0 0.0 0.0"/> -->
      <geometry>
        <mesh filename="package://kuka_kr6_support/meshes/kr6r700sixx/collision/link_2.stl"/>        
      </geometry>
    </collision>
  </link>
  <link name="link_3">
  <inertial>
      <origin xyz="0.0 0.0 0.0" rpy="0.0 0.0 0.0"/>
      <mass value="1.0"/>
      <inertia ixx="0.0" ixy="0.0" ixz="0.0" iyy="0.0" iyz="0.0" izz="0.0"/>
    </inertial>
    <visual>
      <origin rpy="0 0 0" xyz="0 0 0"/>
      <geometry>
        <mesh filename="package://kuka_kr6_support/meshes/kr6_agilus/visual/link_3.dae"/>
      </geometry>
      <xacro:material_kuka_orange />
    </visual>
    <collision>
      <!-- <origin xyz="0.0 0.0 0.0" rpy="0.0 0.0 0.0"/> -->
      <geometry>
        <mesh filename="package://kuka_kr6_support/meshes/kr6_agilus/collision/link_3.stl"/>        
      </geometry>
    </collision>
  </link>
  <link name="link_4">
  <inertial>
      <origin xyz="0.0 0.0 0.0" rpy="0.0 0.0 0.0"/>
      <mass value="1.0"/>
      <inertia ixx="0.0" ixy="0.0" ixz="0.0" iyy="0.0" iyz="0.0" izz="0.0"/>
    </inertial>
    <visual>
      <origin rpy="0 0 0" xyz="0 0 0"/>
      <geometry>
        <mesh filename="package://kuka_kr6_support/meshes/kr6r700sixx/visual/link_4.dae"/>
      </geometry>
      <xacro:material_kuka_orange />
    </visual>
    <collision>
      <!-- <origin xyz="0.0 0.0 0.0" rpy="0.0 0.0 0.0"/> -->
      <geometry>
        <mesh filename="package://kuka_kr6_support/meshes/kr6r700sixx/collision/link_4.stl"/>        
      </geometry>
    </collision>
  </link>
  <link name="link_5">
  <inertial>
      <origin xyz="0.0 0.0 0.0" rpy="0.0 0.0 0.0"/>
      <mass value="1.0"/>
      <inertia ixx="0.0" ixy="0.0" ixz="0.0" iyy="0.0" iyz="0.0" izz="0.0"/>
    </inertial>
    <visual>
      <origin rpy="0 0 0" xyz="0 0 0"/>
      <geometry>
        <mesh filename="package://kuka_kr6_support/meshes/kr6_agilus/visual/link_5.dae"/>
      </geometry>
      <xacro:material_kuka_orange />
    </visual>
    <collision>
      <!-- <origin xyz="0.0 0.0 0.0" rpy="0.0 0.0 0.0"/> -->
      <geometry>
        <mesh filename="package://kuka_kr6_support/meshes/kr6_agilus/collision/link_5.stl"/>        
      </geometry>
    </collision>
  </link>
  <link name="link_6">
  <inertial>
      <origin xyz="0.0 0.0 0.0" rpy="0.0 0.0 0.0"/>
      <mass value="1.0"/>
      <inertia ixx="0.0" ixy="0.0" ixz="0.0" iyy="0.0" iyz="0.0" izz="0.0"/>
    </inertial>
    <visual>
      <origin rpy="0 0 0" xyz="0 0 0"/>
      <geometry>
        <mesh filename="package://kuka_kr6_support/meshes/kr6_agilus/visual/link_6.dae"/>
      </geometry>
      <xacro:material_kuka_orange />
    </visual>
    <collision>
      <!-- <origin xyz="0.0 0.0 0.0" rpy="0.0 0.0 0.0"/> -->
      <geometry>
        <mesh filename="package://kuka_kr6_support/meshes/kr6_agilus/collision/link_6.stl"/>        
      </geometry>
    </collision>
  </link>
  <link name="tool0">
    <visual>
    <origin rpy="0 0 0" xyz="0 0 0"/>
      <geometry>
			<mesh filename="../cube.obj" scale=".03 .03 .2"/>
      </geometry>
       <material name="red">
        <color rgba="0 1 0 1"/>
      </material>
    </visual>
    <collision>
      <origin rpy="0 0 0" xyz="0 0 0"/>
      <geometry>
	 	  <box size=".03 .03 .2"/>
      </geometry>
    </collision>
  </link>
  <joint type="revolute" name="joint_1">
    <origin xyz="0 0 0.4" rpy="0 0 0"/>
      <parent link="base_link"/>
      <child link="link_1"/>
      <axis xyz="0 0 -1"/>
      <limit lower="-2.9670597283903604" upper="2.9670597283903604" effort="0" velocity="6.283185307179586"/>
  </joint>
  <joint type="revolute" name="joint_2">
    <origin xyz="0.025 0 0" rpy="0 0 0"/>
      <parent link="link_1"/>
      <child link="link_2"/>
      <axis xyz="0 1 0"/>
      <limit lower="-3.3161255787892263" upper="0.7853981633974483" effort="0" velocity="5.235987755982989"/>
  </joint>
  <joint type="revolute" name="joint_3">
    <origin xyz="0.315 0 0" rpy="0 0 0"/>
      <parent link="link_2"/>
      <child link="link_3"/>
      <axis xyz="0 1 0"/>
      <limit lower="-2.0943951023931953" upper="2.722713633111154" effort="0" velocity="6.283185307179586"/>
  </joint>
  <joint type="revolute" name="joint_4">
    <origin xyz="0 0 0.035" rpy="0 0 0"/>
      <parent link="link_3"/>
      <child link="link_4"/>
      <axis xyz="-1 0 0"/>
      <limit lower="-3.2288591161895095" upper="3.2288591161895095" effort="0" velocity="6.649704450098396"/>
  </joint>
  <joint type="revolute" name="joint_5">
    <origin xyz="0.365 0 0" rpy="0 0 0"/>
      <parent link="link_4"/>
      <child link="link_5"/>
      <axis xyz="0 1 0"/>
      <limit lower="-2.0943951023931953" upper="2.0943951023931953" effort="0" velocity="6.771877497737998"/>
  </joint>
  <joint type="revolute" name="joint_6">
    <origin xyz="0.080 0 0" rpy="0 0 0"/>
      <parent link="link_5"/>
      <child link="link_6"/>
      <axis xyz="-1 0 0"/>
      <limit lower="-6.1086523819801535" upper="6.1086523819801535" effort="0" velocity="10.733774899765127"/>
  </joint>
  <joint type="fixed" name="joint_6-tool0">
    <parent link="link_6"/>
    <child link="tool0"/>
    <origin xyz="0 0 0" rpy="0 1.57079632679 0"/>
  </joint> 
  <link name="base">
  <inertial>
      <origin xyz="0.0 0.0 0.0" rpy="0.0 0.0 0.0"/>
      <mass value="1.0"/>
      <inertia ixx="0.0" ixy="0.0" ixz="0.0" iyy="0.0" iyz="0.0" izz="0.0"/>
    </inertial>
  </link>
  <joint name="base_link-base" type="fixed">
    <origin xyz="0 0 0" rpy="0 0 0"/>
    <parent link="base_link"/>
    <child link="base"/>
  </joint>
</robot>