<?xml version="1.0" ?>
<!-- =================================================================================== -->
<!-- |    This document was autogenerated by xacro from kuka-model.xacro               | -->
<!-- |    EDITING THIS FILE BY HAND IS NOT RECOMMENDED                                 | -->
<!-- =================================================================================== -->
<robot name="kuka-model" xmlns:xacro="http://www.ros.org/wiki/xacro">
  <!-- Prefix for joints and links -->
  <!-- KUKA software joint limits -5 degrees -->
  <!-- Axis a2 gedit and a3 offset (wrt KUKA axis angles) not includied here (view joints definitions)-->
  <!-- Alpha value for KUKA Shadow -->
  <!-- Links -->
  <link name="base">
    <visual>
      <origin rpy="0 0 0" xyz="0 0 0"/>
      <geometry>
        <mesh filename="package://kuka_kr6_support/meshes/kr6_agilus/visual/base_link.dae"/>
      </geometry>
      <material name="">
        <color rgba="0.2 0.2 0.2 1"/>
      </material>
    </visual>
    <collision>
      <origin rpy="0 0 0" xyz="0 0 0"/>
      <geometry>
        <mesh filename="package://kuka_kr6_support/meshes/kr6_agilus/collision/base_link.stl"/>
      </geometry>
    </collision>
  </link>
  <link name="link_1">
    <inertial>
      <origin rpy="0 0 0" xyz="0.11674 0.022325 0.17065"/>
      <mass value="33.045"/>
      <inertia ixx="0.96011" ixy="0.14584" ixz="0.51813" iyy="1.5289" iyz="0.11532" izz="1.3182"/>
    </inertial>
    <visual>
      <origin rpy="0 0 0" xyz="0 0 0"/>
      <geometry>
        <mesh filename="package://kuka_kr6_support/meshes/kr6_agilus/visual/link_1.dae"/>
      </geometry>
      <material name="">
        <color rgba="0.94 0.590 0.08 1"/>
      </material>
    </visual>
    <collision>
      <origin rpy="0 0 0" xyz="0 0 0"/>
      <geometry>
        <mesh filename="package://kuka_kr6_support/meshes/kr6_agilus/collision/link_1.stl"/>
      </geometry>
    </collision>
  </link>
  <link name="link_2">
    <inertial>
      <origin rpy="0 0 0" xyz="-5.1658E-05 -0.076847 0.27349"/>
      <mass value="14.509"/>
      <inertia ixx="0.64764" ixy="6.686E-05" ixz="8.7057E-06" iyy="0.64831" iyz="-0.0047" izz="0.052771"/>
    </inertial>
    <visual>
      <origin rpy="0 0 0" xyz="0 0 0"/>
      <geometry>
        <mesh filename="package://kuka_kr6_support/meshes/kr6r700sixx/visual/link_2.dae"/>
      </geometry>
      <material name="">
        <color rgba="0.94 0.590 0.08 1"/>
      </material>
    </visual>
    <collision>
      <origin rpy="0 0 0" xyz="0 0 0"/>
      <geometry>
        <mesh filename="package://kuka_kr6_support/meshes/kr6r700sixx/collision/link_2.stl"/>
      </geometry>
    </collision>
  </link>
  <link name="link_3">
    <inertial>
      <origin rpy="0 0 0" xyz="0.0026683 0.11641 0.087839"/>
      <mass value="13.751"/>
      <inertia ixx="0.15848" ixy="-0.021262" ixz="0.002384" iyy="0.32598" iyz="-0.0032541" izz="0.28494"/>
    </inertial>
    <visual>
      <origin rpy="0 0 0" xyz="0 0 0"/>
      <geometry>
        <mesh filename="package://kuka_kr6_support/meshes/kr6_agilus/visual/link_3.dae"/>
      </geometry>
      <material name="">
        <color rgba="0.94 0.590 0.08 1"/>
      </material>
    </visual>
    <collision>
      <origin rpy="0 0 0" xyz="0 0 0"/>
      <geometry>
        <mesh filename="package://kuka_kr6_support/meshes/kr6_agilus/collision/link_3.stl"/>
      </geometry>
    </collision>
  </link>
  <link name="link_4">
    <inertial>
      <origin rpy="0 0 0" xyz="0.11605 0.011227 -0.0003921"/>
      <mass value="2.1033"/>
      <inertia ixx="0.0040841" ixy="0.0015385" ixz="-5.3731E-05" iyy="0.012206" iyz="-5.7395E-05" izz="0.013848"/>
    </inertial>
    <visual>
      <origin rpy="0 0 0" xyz="0 0 0"/>
      <geometry>
        <mesh filename="package://kuka_kr6_support/meshes/kr6r700sixx/visual/link_4.dae"/>
      </geometry>
      <material name="">
        <color rgba="0.94 0.590 0.08 1"/>
      </material>
    </visual>
    <collision>
      <origin rpy="0 0 0" xyz="0 0 0"/>
      <geometry>
        <mesh filename="package://kuka_kr6_support/meshes/kr6r700sixx/collision/link_4.stl"/>
      </geometry>
    </collision>
  </link>
  <link name="link_5">
    <inertial>
      <origin rpy="0 0 0" xyz="0.023271 -0.036872 4.3221E-10"/>
      <mass value="0.64815"/>
      <inertia ixx="0.00060616" ixy="0.00023977" ixz="4.1189E-12" iyy="0.0012368" iyz="-1.4095E-13" izz="0.0013528"/>
    </inertial>
    <visual>
      <origin rpy="0 0 0" xyz="0 0 0"/>
      <geometry>
        <mesh filename="package://kuka_kr6_support/meshes/kr6_agilus/visual/link_5.dae"/>
      </geometry>
      <material name="">
        <color rgba="0.94 0.590 0.08 1"/>
      </material>
    </visual>
    <collision>
      <origin rpy="0 0 0" xyz="0 0 0"/>
      <geometry>
        <mesh filename="package://kuka_kr6_support/meshes/kr6_agilus/collision/link_5.stl"/>
      </geometry>
    </collision>
  </link>
  <link name="link_6">
    <inertial>
      <origin rpy="0 0 0" xyz="0.0065821 3.3266E-05 -0.00027413"/>
      <mass value="0.023044"/>
      <inertia ixx="1.0462E-05" ixy="1.3009E-09" ixz="-1.072E-08" iyy="5.6691E-06" iyz="-3.9092E-08" izz="5.3518E-06"/>
    </inertial>
    <visual>
      <origin rpy="0 0 0" xyz="0 0 0"/>
      <geometry>
        <mesh filename="package://kuka_kr6_support/meshes/kr6_agilus/visual/link_6.dae"/>
      </geometry>
      <material name="">
        <color rgba="0.74 0.74 0.74 1"/>
      </material>
    </visual>
    <collision>
      <origin rpy="0 0 0" xyz="0 0 0"/>
      <geometry>
        <mesh filename="package://kuka_kr6_support/meshes/kr6_agilus/collision/link_6.stl"/>
      </geometry>
    </collision>
  </link>
  <!-- Joints -->
  <joint name="a1" type="revolute">
    <origin rpy="0 0 0" xyz="0 0 0.4"/>
    <parent link="base"/>
    <child link="link_1"/>
    <axis xyz="0 0 -1"/>
    <limit effort="0" lower="-2.9670597283903604" upper="2.9670597283903604" velocity="2.6529"/>
  </joint>
  <joint name="a2" type="revolute">
    <origin rpy="0 0 0" xyz="0.025 0 0"/>
    <parent link="link_1"/>
    <child link="link_2"/>
    <axis xyz="0 1 0"/>
    <!-- Offset de -90 -->
    <limit effort="0" lower="-3.3161255787892263" upper="0.7853981633974483" velocity="2.6529"/>
  </joint>
  <joint name="a3" type="revolute">
    <origin rpy="0 0 0" xyz="0.315 0 0"/>
    <parent link="link_2"/>
    <child link="link_3"/>
    <axis xyz="0 0.99939 -0.034899"/>
    <!-- Offset +90 -->
    <limit effort="0" lower="-2.0943951023931953" upper="2.722713633111154" velocity="2.6529"/>
  </joint>
  <joint name="a4" type="revolute">
    <origin rpy="0 0 0" xyz="0 0 0.035"/>
    <parent link="link_3"/>
    <child link="link_4"/>
    <axis xyz="-1 0 0"/>
    <limit effort="0" lower="-3.2288591161895095" upper="3.2288591161895095" velocity="4.3633"/>
  </joint>
  <joint name="a5" type="revolute">
    <origin rpy="0 0 0" xyz="0.365 0 0"/>
    <parent link="link_4"/>
    <child link="link_5"/>
    <axis xyz="0 1 0"/>
    <limit effort="0" lower="-2.0943951023931953" upper="2.0943951023931953" velocity="6.2308"/>
  </joint>
  <joint name="a6" type="revolute">
    <origin rpy="0 0 0" xyz="0.080 0 0"/>
    <parent link="link_5"/>
    <child link="link_6"/>
    <axis xyz="-1 0 0"/>
    <limit effort="0" lower="-6.1086523819801535" upper="6.1086523819801535" velocity="11.519"/>
  </joint>
  <!-- Include tool -->
</robot>